[2023-01-24 03:41:53,423] {taskinstance.py:1179} INFO - Dependencies all met for <TaskInstance: Respuesta_Nasa.Leer_Datos_Respuesta_Satelite scheduled__2023-01-02T00:00:00+00:00 [queued]>
[2023-01-24 03:41:53,435] {taskinstance.py:1179} INFO - Dependencies all met for <TaskInstance: Respuesta_Nasa.Leer_Datos_Respuesta_Satelite scheduled__2023-01-02T00:00:00+00:00 [queued]>
[2023-01-24 03:41:53,435] {taskinstance.py:1376} INFO - 
--------------------------------------------------------------------------------
[2023-01-24 03:41:53,435] {taskinstance.py:1377} INFO - Starting attempt 4 of 6
[2023-01-24 03:41:53,435] {taskinstance.py:1378} INFO - 
--------------------------------------------------------------------------------
[2023-01-24 03:41:53,449] {taskinstance.py:1397} INFO - Executing <Task(BashOperator): Leer_Datos_Respuesta_Satelite> on 2023-01-02 00:00:00+00:00
[2023-01-24 03:41:53,454] {standard_task_runner.py:52} INFO - Started process 2668 to run task
[2023-01-24 03:41:53,457] {standard_task_runner.py:79} INFO - Running: ['***', 'tasks', 'run', 'Respuesta_Nasa', 'Leer_Datos_Respuesta_Satelite', 'scheduled__2023-01-02T00:00:00+00:00', '--job-id', '450', '--raw', '--subdir', 'DAGS_FOLDER/00-ETL_spaceX.py', '--cfg-path', '/tmp/tmpq3_j26rm', '--error-file', '/tmp/tmplimkqlh0']
[2023-01-24 03:41:53,459] {standard_task_runner.py:80} INFO - Job 450: Subtask Leer_Datos_Respuesta_Satelite
[2023-01-24 03:41:53,527] {task_command.py:371} INFO - Running <TaskInstance: Respuesta_Nasa.Leer_Datos_Respuesta_Satelite scheduled__2023-01-02T00:00:00+00:00 [running]> on host fd9891b969b0
[2023-01-24 03:41:53,612] {taskinstance.py:1591} INFO - Exporting the following env vars:
AIRFLOW_CTX_DAG_OWNER=me
AIRFLOW_CTX_DAG_ID=Respuesta_Nasa
AIRFLOW_CTX_TASK_ID=Leer_Datos_Respuesta_Satelite
AIRFLOW_CTX_EXECUTION_DATE=2023-01-02T00:00:00+00:00
AIRFLOW_CTX_TRY_NUMBER=4
AIRFLOW_CTX_DAG_RUN_ID=scheduled__2023-01-02T00:00:00+00:00
[2023-01-24 03:41:53,614] {subprocess.py:62} INFO - Tmp dir root location: 
 /tmp
[2023-01-24 03:41:53,614] {subprocess.py:74} INFO - Running command: ['bash', '-c', 'ls /tmp && head /tmp/platzi_data_20230102.csv']
[2023-01-24 03:41:53,626] {subprocess.py:85} INFO - Output:
[2023-01-24 03:41:53,629] {subprocess.py:92} INFO - ***tmp8hgvvtv1
[2023-01-24 03:41:53,629] {subprocess.py:92} INFO - ***tmpd1sbos_u
[2023-01-24 03:41:53,630] {subprocess.py:92} INFO - platzi_data_20210101.csv
[2023-01-24 03:41:53,630] {subprocess.py:92} INFO - platzi_data_{{ds_nodash}}.csv
[2023-01-24 03:41:53,630] {subprocess.py:92} INFO - pymp-_z20wx4h
[2023-01-24 03:41:53,630] {subprocess.py:92} INFO - pymp-igsi0xnb
[2023-01-24 03:41:53,630] {subprocess.py:92} INFO - response_20230101.txt
[2023-01-24 03:41:53,630] {subprocess.py:92} INFO - response_20230102.txt
[2023-01-24 03:41:53,630] {subprocess.py:92} INFO - response_20230103.txt
[2023-01-24 03:41:53,631] {subprocess.py:92} INFO - spacex_20230101.json
[2023-01-24 03:41:53,631] {subprocess.py:92} INFO - spacex_20230102.json
[2023-01-24 03:41:53,631] {subprocess.py:92} INFO - spacex_20230103.json
[2023-01-24 03:41:53,631] {subprocess.py:92} INFO - tmpb_pqdwmc
[2023-01-24 03:41:53,631] {subprocess.py:92} INFO - tmpfkygnkny
[2023-01-24 03:41:53,631] {subprocess.py:92} INFO - tmplimkqlh0
[2023-01-24 03:41:53,631] {subprocess.py:92} INFO - tmpnvc2r2ky
[2023-01-24 03:41:53,632] {subprocess.py:92} INFO - head: cannot open '/tmp/platzi_data_20230102.csv' for reading: No such file or directory
[2023-01-24 03:41:53,632] {subprocess.py:96} INFO - Command exited with return code 1
[2023-01-24 03:41:53,648] {taskinstance.py:1909} ERROR - Task failed with exception
Traceback (most recent call last):
  File "/home/airflow/.local/lib/python3.7/site-packages/airflow/operators/bash.py", line 195, in execute
    f'Bash command failed. The command returned a non-zero exit code {result.exit_code}.'
airflow.exceptions.AirflowException: Bash command failed. The command returned a non-zero exit code 1.
[2023-01-24 03:41:53,652] {taskinstance.py:1420} INFO - Marking task as UP_FOR_RETRY. dag_id=Respuesta_Nasa, task_id=Leer_Datos_Respuesta_Satelite, execution_date=20230102T000000, start_date=20230124T034153, end_date=20230124T034153
[2023-01-24 03:41:53,667] {standard_task_runner.py:97} ERROR - Failed to execute job 450 for task Leer_Datos_Respuesta_Satelite (Bash command failed. The command returned a non-zero exit code 1.; 2668)
[2023-01-24 03:41:53,709] {local_task_job.py:156} INFO - Task exited with return code 1
[2023-01-24 03:41:53,756] {local_task_job.py:273} INFO - 0 downstream tasks scheduled from follow-on schedule check
