[2023-01-24 03:41:53,449] {taskinstance.py:1179} INFO - Dependencies all met for <TaskInstance: Respuesta_Nasa.Leer_Datos_Respuesta_Satelite scheduled__2023-01-01T00:00:00+00:00 [queued]>
[2023-01-24 03:41:53,461] {taskinstance.py:1179} INFO - Dependencies all met for <TaskInstance: Respuesta_Nasa.Leer_Datos_Respuesta_Satelite scheduled__2023-01-01T00:00:00+00:00 [queued]>
[2023-01-24 03:41:53,461] {taskinstance.py:1376} INFO - 
--------------------------------------------------------------------------------
[2023-01-24 03:41:53,461] {taskinstance.py:1377} INFO - Starting attempt 4 of 6
[2023-01-24 03:41:53,462] {taskinstance.py:1378} INFO - 
--------------------------------------------------------------------------------
[2023-01-24 03:41:53,478] {taskinstance.py:1397} INFO - Executing <Task(BashOperator): Leer_Datos_Respuesta_Satelite> on 2023-01-01 00:00:00+00:00
[2023-01-24 03:41:53,483] {standard_task_runner.py:52} INFO - Started process 2670 to run task
[2023-01-24 03:41:53,486] {standard_task_runner.py:79} INFO - Running: ['***', 'tasks', 'run', 'Respuesta_Nasa', 'Leer_Datos_Respuesta_Satelite', 'scheduled__2023-01-01T00:00:00+00:00', '--job-id', '452', '--raw', '--subdir', 'DAGS_FOLDER/00-ETL_spaceX.py', '--cfg-path', '/tmp/tmpwfldhb1v', '--error-file', '/tmp/tmpb_pqdwmc']
[2023-01-24 03:41:53,487] {standard_task_runner.py:80} INFO - Job 452: Subtask Leer_Datos_Respuesta_Satelite
[2023-01-24 03:41:53,553] {task_command.py:371} INFO - Running <TaskInstance: Respuesta_Nasa.Leer_Datos_Respuesta_Satelite scheduled__2023-01-01T00:00:00+00:00 [running]> on host fd9891b969b0
[2023-01-24 03:41:53,635] {taskinstance.py:1591} INFO - Exporting the following env vars:
AIRFLOW_CTX_DAG_OWNER=me
AIRFLOW_CTX_DAG_ID=Respuesta_Nasa
AIRFLOW_CTX_TASK_ID=Leer_Datos_Respuesta_Satelite
AIRFLOW_CTX_EXECUTION_DATE=2023-01-01T00:00:00+00:00
AIRFLOW_CTX_TRY_NUMBER=4
AIRFLOW_CTX_DAG_RUN_ID=scheduled__2023-01-01T00:00:00+00:00
[2023-01-24 03:41:53,636] {subprocess.py:62} INFO - Tmp dir root location: 
 /tmp
[2023-01-24 03:41:53,637] {subprocess.py:74} INFO - Running command: ['bash', '-c', 'ls /tmp && head /tmp/platzi_data_20230101.csv']
[2023-01-24 03:41:53,648] {subprocess.py:85} INFO - Output:
[2023-01-24 03:41:53,652] {subprocess.py:92} INFO - ***tmp8p01ojjv
[2023-01-24 03:41:53,652] {subprocess.py:92} INFO - platzi_data_20210101.csv
[2023-01-24 03:41:53,653] {subprocess.py:92} INFO - platzi_data_{{ds_nodash}}.csv
[2023-01-24 03:41:53,653] {subprocess.py:92} INFO - pymp-_z20wx4h
[2023-01-24 03:41:53,653] {subprocess.py:92} INFO - pymp-igsi0xnb
[2023-01-24 03:41:53,653] {subprocess.py:92} INFO - response_20230101.txt
[2023-01-24 03:41:53,653] {subprocess.py:92} INFO - response_20230102.txt
[2023-01-24 03:41:53,653] {subprocess.py:92} INFO - response_20230103.txt
[2023-01-24 03:41:53,653] {subprocess.py:92} INFO - spacex_20230101.json
[2023-01-24 03:41:53,653] {subprocess.py:92} INFO - spacex_20230102.json
[2023-01-24 03:41:53,653] {subprocess.py:92} INFO - spacex_20230103.json
[2023-01-24 03:41:53,653] {subprocess.py:92} INFO - tmpb_pqdwmc
[2023-01-24 03:41:53,653] {subprocess.py:92} INFO - tmpfkygnkny
[2023-01-24 03:41:53,653] {subprocess.py:92} INFO - tmplimkqlh0
[2023-01-24 03:41:53,654] {subprocess.py:92} INFO - tmpnvc2r2ky
[2023-01-24 03:41:53,654] {subprocess.py:92} INFO - head: cannot open '/tmp/platzi_data_20230101.csv' for reading: No such file or directory
[2023-01-24 03:41:53,654] {subprocess.py:96} INFO - Command exited with return code 1
[2023-01-24 03:41:53,671] {taskinstance.py:1909} ERROR - Task failed with exception
Traceback (most recent call last):
  File "/home/airflow/.local/lib/python3.7/site-packages/airflow/operators/bash.py", line 195, in execute
    f'Bash command failed. The command returned a non-zero exit code {result.exit_code}.'
airflow.exceptions.AirflowException: Bash command failed. The command returned a non-zero exit code 1.
[2023-01-24 03:41:53,675] {taskinstance.py:1420} INFO - Marking task as UP_FOR_RETRY. dag_id=Respuesta_Nasa, task_id=Leer_Datos_Respuesta_Satelite, execution_date=20230101T000000, start_date=20230124T034153, end_date=20230124T034153
[2023-01-24 03:41:53,688] {standard_task_runner.py:97} ERROR - Failed to execute job 452 for task Leer_Datos_Respuesta_Satelite (Bash command failed. The command returned a non-zero exit code 1.; 2670)
[2023-01-24 03:41:53,697] {local_task_job.py:156} INFO - Task exited with return code 1
[2023-01-24 03:41:53,737] {local_task_job.py:273} INFO - 0 downstream tasks scheduled from follow-on schedule check
