[2023-01-24 03:37:59,670] {taskinstance.py:1179} INFO - Dependencies all met for <TaskInstance: Respuesta_Nasa.Leer_Datos_Respuesta_Satelite scheduled__2023-01-03T00:00:00+00:00 [queued]>
[2023-01-24 03:37:59,685] {taskinstance.py:1179} INFO - Dependencies all met for <TaskInstance: Respuesta_Nasa.Leer_Datos_Respuesta_Satelite scheduled__2023-01-03T00:00:00+00:00 [queued]>
[2023-01-24 03:37:59,685] {taskinstance.py:1376} INFO - 
--------------------------------------------------------------------------------
[2023-01-24 03:37:59,685] {taskinstance.py:1377} INFO - Starting attempt 1 of 3
[2023-01-24 03:37:59,685] {taskinstance.py:1378} INFO - 
--------------------------------------------------------------------------------
[2023-01-24 03:37:59,700] {taskinstance.py:1397} INFO - Executing <Task(BashOperator): Leer_Datos_Respuesta_Satelite> on 2023-01-03 00:00:00+00:00
[2023-01-24 03:37:59,705] {standard_task_runner.py:52} INFO - Started process 2377 to run task
[2023-01-24 03:37:59,708] {standard_task_runner.py:79} INFO - Running: ['***', 'tasks', 'run', 'Respuesta_Nasa', 'Leer_Datos_Respuesta_Satelite', 'scheduled__2023-01-03T00:00:00+00:00', '--job-id', '426', '--raw', '--subdir', 'DAGS_FOLDER/00-ETL_spaceX.py', '--cfg-path', '/tmp/tmpx1246p62', '--error-file', '/tmp/tmpqsdshs6o']
[2023-01-24 03:37:59,710] {standard_task_runner.py:80} INFO - Job 426: Subtask Leer_Datos_Respuesta_Satelite
[2023-01-24 03:37:59,780] {task_command.py:371} INFO - Running <TaskInstance: Respuesta_Nasa.Leer_Datos_Respuesta_Satelite scheduled__2023-01-03T00:00:00+00:00 [running]> on host fd9891b969b0
[2023-01-24 03:37:59,863] {taskinstance.py:1591} INFO - Exporting the following env vars:
AIRFLOW_CTX_DAG_OWNER=me
AIRFLOW_CTX_DAG_ID=Respuesta_Nasa
AIRFLOW_CTX_TASK_ID=Leer_Datos_Respuesta_Satelite
AIRFLOW_CTX_EXECUTION_DATE=2023-01-03T00:00:00+00:00
AIRFLOW_CTX_TRY_NUMBER=1
AIRFLOW_CTX_DAG_RUN_ID=scheduled__2023-01-03T00:00:00+00:00
[2023-01-24 03:37:59,865] {subprocess.py:62} INFO - Tmp dir root location: 
 /tmp
[2023-01-24 03:37:59,865] {subprocess.py:74} INFO - Running command: ['bash', '-c', 'ls /tmp && head /tmp/platzi_data_20230103.csv']
[2023-01-24 03:37:59,876] {subprocess.py:85} INFO - Output:
[2023-01-24 03:37:59,880] {subprocess.py:92} INFO - ***tmpfm58mrku
[2023-01-24 03:37:59,880] {subprocess.py:92} INFO - ***tmphij4xng1
[2023-01-24 03:37:59,880] {subprocess.py:92} INFO - platzi_data_20210101.csv
[2023-01-24 03:37:59,880] {subprocess.py:92} INFO - pymp-_z20wx4h
[2023-01-24 03:37:59,880] {subprocess.py:92} INFO - pymp-igsi0xnb
[2023-01-24 03:37:59,880] {subprocess.py:92} INFO - response_20230101.txt
[2023-01-24 03:37:59,880] {subprocess.py:92} INFO - response_20230102.txt
[2023-01-24 03:37:59,881] {subprocess.py:92} INFO - response_20230103.txt
[2023-01-24 03:37:59,881] {subprocess.py:92} INFO - spacex_20230101.json
[2023-01-24 03:37:59,881] {subprocess.py:92} INFO - spacex_20230102.json
[2023-01-24 03:37:59,881] {subprocess.py:92} INFO - spacex_20230103.json
[2023-01-24 03:37:59,881] {subprocess.py:92} INFO - tmp5m2duynx
[2023-01-24 03:37:59,881] {subprocess.py:92} INFO - tmpj3qhqqh3
[2023-01-24 03:37:59,881] {subprocess.py:92} INFO - tmpnvc2r2ky
[2023-01-24 03:37:59,881] {subprocess.py:92} INFO - tmpqsdshs6o
[2023-01-24 03:37:59,881] {subprocess.py:92} INFO - head: cannot open '/tmp/platzi_data_20230103.csv' for reading: No such file or directory
[2023-01-24 03:37:59,882] {subprocess.py:96} INFO - Command exited with return code 1
[2023-01-24 03:37:59,897] {taskinstance.py:1909} ERROR - Task failed with exception
Traceback (most recent call last):
  File "/home/airflow/.local/lib/python3.7/site-packages/airflow/operators/bash.py", line 195, in execute
    f'Bash command failed. The command returned a non-zero exit code {result.exit_code}.'
airflow.exceptions.AirflowException: Bash command failed. The command returned a non-zero exit code 1.
[2023-01-24 03:37:59,901] {taskinstance.py:1420} INFO - Marking task as UP_FOR_RETRY. dag_id=Respuesta_Nasa, task_id=Leer_Datos_Respuesta_Satelite, execution_date=20230103T000000, start_date=20230124T033759, end_date=20230124T033759
[2023-01-24 03:37:59,914] {standard_task_runner.py:97} ERROR - Failed to execute job 426 for task Leer_Datos_Respuesta_Satelite (Bash command failed. The command returned a non-zero exit code 1.; 2377)
[2023-01-24 03:37:59,960] {local_task_job.py:156} INFO - Task exited with return code 1
[2023-01-24 03:38:00,079] {local_task_job.py:273} INFO - 0 downstream tasks scheduled from follow-on schedule check
