[2023-01-24 03:43:56,941] {taskinstance.py:1179} INFO - Dependencies all met for <TaskInstance: Respuesta_Nasa.Leer_Datos_Respuesta_Satelite scheduled__2023-01-03T00:00:00+00:00 [queued]>
[2023-01-24 03:43:56,954] {taskinstance.py:1179} INFO - Dependencies all met for <TaskInstance: Respuesta_Nasa.Leer_Datos_Respuesta_Satelite scheduled__2023-01-03T00:00:00+00:00 [queued]>
[2023-01-24 03:43:56,955] {taskinstance.py:1376} INFO - 
--------------------------------------------------------------------------------
[2023-01-24 03:43:56,955] {taskinstance.py:1377} INFO - Starting attempt 6 of 6
[2023-01-24 03:43:56,955] {taskinstance.py:1378} INFO - 
--------------------------------------------------------------------------------
[2023-01-24 03:43:56,972] {taskinstance.py:1397} INFO - Executing <Task(BashOperator): Leer_Datos_Respuesta_Satelite> on 2023-01-03 00:00:00+00:00
[2023-01-24 03:43:56,976] {standard_task_runner.py:52} INFO - Started process 2789 to run task
[2023-01-24 03:43:56,980] {standard_task_runner.py:79} INFO - Running: ['***', 'tasks', 'run', 'Respuesta_Nasa', 'Leer_Datos_Respuesta_Satelite', 'scheduled__2023-01-03T00:00:00+00:00', '--job-id', '456', '--raw', '--subdir', 'DAGS_FOLDER/00-ETL_spaceX.py', '--cfg-path', '/tmp/tmps4x1njcm', '--error-file', '/tmp/tmp7htmkt2w']
[2023-01-24 03:43:56,982] {standard_task_runner.py:80} INFO - Job 456: Subtask Leer_Datos_Respuesta_Satelite
[2023-01-24 03:43:57,065] {task_command.py:371} INFO - Running <TaskInstance: Respuesta_Nasa.Leer_Datos_Respuesta_Satelite scheduled__2023-01-03T00:00:00+00:00 [running]> on host fd9891b969b0
[2023-01-24 03:43:57,155] {taskinstance.py:1591} INFO - Exporting the following env vars:
AIRFLOW_CTX_DAG_OWNER=me
AIRFLOW_CTX_DAG_ID=Respuesta_Nasa
AIRFLOW_CTX_TASK_ID=Leer_Datos_Respuesta_Satelite
AIRFLOW_CTX_EXECUTION_DATE=2023-01-03T00:00:00+00:00
AIRFLOW_CTX_TRY_NUMBER=6
AIRFLOW_CTX_DAG_RUN_ID=scheduled__2023-01-03T00:00:00+00:00
[2023-01-24 03:43:57,156] {subprocess.py:62} INFO - Tmp dir root location: 
 /tmp
[2023-01-24 03:43:57,157] {subprocess.py:74} INFO - Running command: ['bash', '-c', 'ls /tmp && head /tmp/platzi_data_20230103.csv']
[2023-01-24 03:43:57,169] {subprocess.py:85} INFO - Output:
[2023-01-24 03:43:57,173] {subprocess.py:92} INFO - ***tmpw19paw3b
[2023-01-24 03:43:57,173] {subprocess.py:92} INFO - ***tmpzpxonthq
[2023-01-24 03:43:57,173] {subprocess.py:92} INFO - platzi_data_20210101.csv
[2023-01-24 03:43:57,173] {subprocess.py:92} INFO - platzi_data_{{ds_nodash}}.csv
[2023-01-24 03:43:57,173] {subprocess.py:92} INFO - pymp-_z20wx4h
[2023-01-24 03:43:57,174] {subprocess.py:92} INFO - pymp-igsi0xnb
[2023-01-24 03:43:57,174] {subprocess.py:92} INFO - response_20230101.txt
[2023-01-24 03:43:57,174] {subprocess.py:92} INFO - response_20230102.txt
[2023-01-24 03:43:57,174] {subprocess.py:92} INFO - response_20230103.txt
[2023-01-24 03:43:57,174] {subprocess.py:92} INFO - spacex_20230101.json
[2023-01-24 03:43:57,174] {subprocess.py:92} INFO - spacex_20230102.json
[2023-01-24 03:43:57,174] {subprocess.py:92} INFO - spacex_20230103.json
[2023-01-24 03:43:57,174] {subprocess.py:92} INFO - tmp7htmkt2w
[2023-01-24 03:43:57,174] {subprocess.py:92} INFO - tmp_hqmdsd7
[2023-01-24 03:43:57,175] {subprocess.py:92} INFO - tmpnvc2r2ky
[2023-01-24 03:43:57,175] {subprocess.py:92} INFO - tmpu3_v7je8
[2023-01-24 03:43:57,175] {subprocess.py:92} INFO - head: cannot open '/tmp/platzi_data_20230103.csv' for reading: No such file or directory
[2023-01-24 03:43:57,175] {subprocess.py:96} INFO - Command exited with return code 1
[2023-01-24 03:43:57,190] {taskinstance.py:1909} ERROR - Task failed with exception
Traceback (most recent call last):
  File "/home/airflow/.local/lib/python3.7/site-packages/airflow/operators/bash.py", line 195, in execute
    f'Bash command failed. The command returned a non-zero exit code {result.exit_code}.'
airflow.exceptions.AirflowException: Bash command failed. The command returned a non-zero exit code 1.
[2023-01-24 03:43:57,194] {taskinstance.py:1420} INFO - Marking task as FAILED. dag_id=Respuesta_Nasa, task_id=Leer_Datos_Respuesta_Satelite, execution_date=20230103T000000, start_date=20230124T034356, end_date=20230124T034357
[2023-01-24 03:43:57,206] {standard_task_runner.py:97} ERROR - Failed to execute job 456 for task Leer_Datos_Respuesta_Satelite (Bash command failed. The command returned a non-zero exit code 1.; 2789)
[2023-01-24 03:43:57,233] {local_task_job.py:156} INFO - Task exited with return code 1
[2023-01-24 03:43:57,286] {local_task_job.py:273} INFO - 0 downstream tasks scheduled from follow-on schedule check
