[2023-01-26T18:20:27.924+0000] {taskinstance.py:1165} INFO - Dependencies all met for <TaskInstance: Respuesta_Nasa.Respuesta_Confirmacion_NASA scheduled__2023-01-01T00:00:00+00:00 [queued]>
[2023-01-26T18:20:27.937+0000] {taskinstance.py:1165} INFO - Dependencies all met for <TaskInstance: Respuesta_Nasa.Respuesta_Confirmacion_NASA scheduled__2023-01-01T00:00:00+00:00 [queued]>
[2023-01-26T18:20:27.937+0000] {taskinstance.py:1362} INFO - 
--------------------------------------------------------------------------------
[2023-01-26T18:20:27.937+0000] {taskinstance.py:1363} INFO - Starting attempt 11 of 13
[2023-01-26T18:20:27.938+0000] {taskinstance.py:1364} INFO - 
--------------------------------------------------------------------------------
[2023-01-26T18:20:27.954+0000] {taskinstance.py:1383} INFO - Executing <Task(BashOperator): Respuesta_Confirmacion_NASA> on 2023-01-01 00:00:00+00:00
[2023-01-26T18:20:27.959+0000] {standard_task_runner.py:55} INFO - Started process 222 to run task
[2023-01-26T18:20:27.963+0000] {standard_task_runner.py:82} INFO - Running: ['***', 'tasks', 'run', 'Respuesta_Nasa', 'Respuesta_Confirmacion_NASA', 'scheduled__2023-01-01T00:00:00+00:00', '--job-id', '682', '--raw', '--subdir', 'DAGS_FOLDER/00-ETL_spaceX.py', '--cfg-path', '/tmp/tmprmbxpm_5']
[2023-01-26T18:20:27.965+0000] {standard_task_runner.py:83} INFO - Job 682: Subtask Respuesta_Confirmacion_NASA
[2023-01-26T18:20:28.030+0000] {task_command.py:376} INFO - Running <TaskInstance: Respuesta_Nasa.Respuesta_Confirmacion_NASA scheduled__2023-01-01T00:00:00+00:00 [running]> on host 3b3ab7bab1a5
[2023-01-26T18:20:28.109+0000] {taskinstance.py:1592} INFO - Exporting the following env vars:
AIRFLOW_CTX_DAG_EMAIL=frandak2@gmail.com
AIRFLOW_CTX_DAG_OWNER=***
AIRFLOW_CTX_DAG_ID=Respuesta_Nasa
AIRFLOW_CTX_TASK_ID=Respuesta_Confirmacion_NASA
AIRFLOW_CTX_EXECUTION_DATE=2023-01-01T00:00:00+00:00
AIRFLOW_CTX_TRY_NUMBER=11
AIRFLOW_CTX_DAG_RUN_ID=scheduled__2023-01-01T00:00:00+00:00
[2023-01-26T18:20:28.111+0000] {subprocess.py:63} INFO - Tmp dir root location: 
 /tmp
[2023-01-26T18:20:28.111+0000] {subprocess.py:75} INFO - Running command: ['/bin/bash', '-c', 'sleep 20 && echo "ConfirmaciÃ³n de la NASA, pueden proceder" > /tmp/response_20230101.txt']
[2023-01-26T18:20:28.123+0000] {subprocess.py:86} INFO - Output:
[2023-01-26T18:20:43.135+0000] {local_task_job.py:223} WARNING - State of this instance has been externally set to restarting. Terminating instance.
[2023-01-26T18:20:43.137+0000] {process_utils.py:133} INFO - Sending Signals.SIGTERM to group 222. PIDs of all processes in the group: [223, 224, 222]
[2023-01-26T18:20:43.137+0000] {process_utils.py:84} INFO - Sending the signal Signals.SIGTERM to group 222
[2023-01-26T18:20:43.137+0000] {taskinstance.py:1562} ERROR - Received SIGTERM. Terminating subprocesses.
[2023-01-26T18:20:43.138+0000] {subprocess.py:104} INFO - Sending SIGTERM signal to process group
[2023-01-26T18:20:43.154+0000] {taskinstance.py:1851} ERROR - Task failed with exception
Traceback (most recent call last):
  File "/home/airflow/.local/lib/python3.7/site-packages/airflow/operators/bash.py", line 191, in execute
    cwd=self.cwd,
  File "/home/airflow/.local/lib/python3.7/site-packages/airflow/hooks/subprocess.py", line 91, in run_command
    for raw_line in iter(self.sub_process.stdout.readline, b''):
  File "/home/airflow/.local/lib/python3.7/site-packages/airflow/models/taskinstance.py", line 1564, in signal_handler
    raise AirflowException("Task received SIGTERM signal")
airflow.exceptions.AirflowException: Task received SIGTERM signal
[2023-01-26T18:20:43.158+0000] {taskinstance.py:1406} INFO - Marking task as UP_FOR_RETRY. dag_id=Respuesta_Nasa, task_id=Respuesta_Confirmacion_NASA, execution_date=20230101T000000, start_date=20230126T182027, end_date=20230126T182043
[2023-01-26T18:20:43.178+0000] {warnings.py:110} WARNING - /home/***/.local/lib/python3.7/site-packages/***/utils/email.py:120: RemovedInAirflow3Warning: Fetching SMTP credentials from configuration variables will be deprecated in a future release. Please set credentials using a connection instead.
  send_mime_email(e_from=mail_from, e_to=recipients, mime_msg=msg, conn_id=conn_id, dryrun=dryrun)

[2023-01-26T18:20:43.179+0000] {configuration.py:569} WARNING - section/key [smtp/smtp_user] not found in config
[2023-01-26T18:20:43.179+0000] {email.py:229} INFO - Email alerting: attempt 1
[2023-01-26T18:20:43.186+0000] {configuration.py:569} WARNING - section/key [smtp/smtp_user] not found in config
[2023-01-26T18:20:43.187+0000] {email.py:229} INFO - Email alerting: attempt 1
[2023-01-26T18:20:43.187+0000] {taskinstance.py:1914} ERROR - Failed to send email to: ['frandak2@gmail.com']
Traceback (most recent call last):
  File "/home/airflow/.local/lib/python3.7/site-packages/airflow/models/taskinstance.py", line 1457, in _run_raw_task
    self._execute_task_with_callbacks(context, test_mode)
  File "/home/airflow/.local/lib/python3.7/site-packages/airflow/models/taskinstance.py", line 1603, in _execute_task_with_callbacks
    result = self._execute_task(context, task_orig)
  File "/home/airflow/.local/lib/python3.7/site-packages/airflow/models/taskinstance.py", line 1664, in _execute_task
    result = execute_callable(context=context)
  File "/home/airflow/.local/lib/python3.7/site-packages/airflow/operators/bash.py", line 191, in execute
    cwd=self.cwd,
  File "/home/airflow/.local/lib/python3.7/site-packages/airflow/hooks/subprocess.py", line 91, in run_command
    for raw_line in iter(self.sub_process.stdout.readline, b''):
  File "/home/airflow/.local/lib/python3.7/site-packages/airflow/models/taskinstance.py", line 1564, in signal_handler
    raise AirflowException("Task received SIGTERM signal")
airflow.exceptions.AirflowException: Task received SIGTERM signal

During handling of the above exception, another exception occurred:

Traceback (most recent call last):
  File "/home/airflow/.local/lib/python3.7/site-packages/airflow/models/taskinstance.py", line 2315, in email_alert
    send_email(task.email, subject, html_content)
  File "/home/airflow/.local/lib/python3.7/site-packages/airflow/utils/email.py", line 72, in send_email
    **kwargs,
  File "/home/airflow/.local/lib/python3.7/site-packages/airflow/utils/email.py", line 120, in send_email_smtp
    send_mime_email(e_from=mail_from, e_to=recipients, mime_msg=msg, conn_id=conn_id, dryrun=dryrun)
  File "/home/airflow/.local/lib/python3.7/site-packages/airflow/utils/email.py", line 231, in send_mime_email
    smtp_conn = _get_smtp_connection(smtp_host, smtp_port, smtp_timeout, smtp_ssl)
  File "/home/airflow/.local/lib/python3.7/site-packages/airflow/utils/email.py", line 265, in _get_smtp_connection
    else smtplib.SMTP(host=host, port=port, timeout=timeout)
  File "/usr/local/lib/python3.7/smtplib.py", line 251, in __init__
    (code, msg) = self.connect(host, port)
  File "/usr/local/lib/python3.7/smtplib.py", line 336, in connect
    self.sock = self._get_socket(host, port, self.timeout)
  File "/usr/local/lib/python3.7/smtplib.py", line 307, in _get_socket
    self.source_address)
  File "/usr/local/lib/python3.7/socket.py", line 728, in create_connection
    raise err
  File "/usr/local/lib/python3.7/socket.py", line 716, in create_connection
    sock.connect(sa)
OSError: [Errno 99] Cannot assign requested address

During handling of the above exception, another exception occurred:

Traceback (most recent call last):
  File "/home/airflow/.local/lib/python3.7/site-packages/airflow/models/taskinstance.py", line 1912, in handle_failure
    self.email_alert(error, task)
  File "/home/airflow/.local/lib/python3.7/site-packages/airflow/models/taskinstance.py", line 2317, in email_alert
    send_email(task.email, subject, html_content_err)
  File "/home/airflow/.local/lib/python3.7/site-packages/airflow/utils/email.py", line 72, in send_email
    **kwargs,
  File "/home/airflow/.local/lib/python3.7/site-packages/airflow/utils/email.py", line 120, in send_email_smtp
    send_mime_email(e_from=mail_from, e_to=recipients, mime_msg=msg, conn_id=conn_id, dryrun=dryrun)
  File "/home/airflow/.local/lib/python3.7/site-packages/airflow/utils/email.py", line 231, in send_mime_email
    smtp_conn = _get_smtp_connection(smtp_host, smtp_port, smtp_timeout, smtp_ssl)
  File "/home/airflow/.local/lib/python3.7/site-packages/airflow/utils/email.py", line 265, in _get_smtp_connection
    else smtplib.SMTP(host=host, port=port, timeout=timeout)
  File "/usr/local/lib/python3.7/smtplib.py", line 251, in __init__
    (code, msg) = self.connect(host, port)
  File "/usr/local/lib/python3.7/smtplib.py", line 336, in connect
    self.sock = self._get_socket(host, port, self.timeout)
  File "/usr/local/lib/python3.7/smtplib.py", line 307, in _get_socket
    self.source_address)
  File "/usr/local/lib/python3.7/socket.py", line 728, in create_connection
    raise err
  File "/usr/local/lib/python3.7/socket.py", line 716, in create_connection
    sock.connect(sa)
OSError: [Errno 99] Cannot assign requested address
[2023-01-26T18:20:43.205+0000] {standard_task_runner.py:105} ERROR - Failed to execute job 682 for task Respuesta_Confirmacion_NASA (Task received SIGTERM signal; 222)
[2023-01-26T18:20:43.230+0000] {process_utils.py:79} INFO - Process psutil.Process(pid=222, status='terminated', exitcode=1, started='18:20:27') (222) terminated with exit code 1
[2023-01-26T18:20:43.231+0000] {process_utils.py:79} INFO - Process psutil.Process(pid=223, status='terminated', started='18:20:27') (223) terminated with exit code None
[2023-01-26T18:20:43.231+0000] {process_utils.py:79} INFO - Process psutil.Process(pid=224, status='terminated', started='18:20:27') (224) terminated with exit code None
