[2023-01-26 18:08:04,190] {taskinstance.py:1179} INFO - Dependencies all met for <TaskInstance: Respuesta_Nasa.send_email_notification scheduled__2023-01-01T00:00:00+00:00 [queued]>
[2023-01-26 18:08:04,202] {taskinstance.py:1179} INFO - Dependencies all met for <TaskInstance: Respuesta_Nasa.send_email_notification scheduled__2023-01-01T00:00:00+00:00 [queued]>
[2023-01-26 18:08:04,202] {taskinstance.py:1376} INFO - 
--------------------------------------------------------------------------------
[2023-01-26 18:08:04,203] {taskinstance.py:1377} INFO - Starting attempt 16 of 18
[2023-01-26 18:08:04,203] {taskinstance.py:1378} INFO - 
--------------------------------------------------------------------------------
[2023-01-26 18:08:04,218] {taskinstance.py:1397} INFO - Executing <Task(EmailOperator): send_email_notification> on 2023-01-01 00:00:00+00:00
[2023-01-26 18:08:04,224] {standard_task_runner.py:52} INFO - Started process 919 to run task
[2023-01-26 18:08:04,227] {standard_task_runner.py:79} INFO - Running: ['***', 'tasks', 'run', 'Respuesta_Nasa', 'send_email_notification', 'scheduled__2023-01-01T00:00:00+00:00', '--job-id', '655', '--raw', '--subdir', 'DAGS_FOLDER/00-ETL_spaceX.py', '--cfg-path', '/tmp/tmp06_i1q6p', '--error-file', '/tmp/tmp4_a2renh']
[2023-01-26 18:08:04,228] {standard_task_runner.py:80} INFO - Job 655: Subtask send_email_notification
[2023-01-26 18:08:04,295] {task_command.py:371} INFO - Running <TaskInstance: Respuesta_Nasa.send_email_notification scheduled__2023-01-01T00:00:00+00:00 [running]> on host da6de88268cf
[2023-01-26 18:08:04,373] {taskinstance.py:1591} INFO - Exporting the following env vars:
AIRFLOW_CTX_DAG_EMAIL=frandak2@gmail.com
AIRFLOW_CTX_DAG_OWNER=***
AIRFLOW_CTX_DAG_ID=Respuesta_Nasa
AIRFLOW_CTX_TASK_ID=send_email_notification
AIRFLOW_CTX_EXECUTION_DATE=2023-01-01T00:00:00+00:00
AIRFLOW_CTX_TRY_NUMBER=16
AIRFLOW_CTX_DAG_RUN_ID=scheduled__2023-01-01T00:00:00+00:00
[2023-01-26 18:08:04,383] {warnings.py:110} WARNING - /home/***/.local/lib/python3.7/site-packages/***/utils/email.py:119: PendingDeprecationWarning: Fetching SMTP credentials from configuration variables will be deprecated in a future release. Please set credentials using a connection instead.
  send_mime_email(e_from=mail_from, e_to=recipients, mime_msg=msg, conn_id=conn_id, dryrun=dryrun)

[2023-01-26 18:08:04,384] {email.py:228} INFO - Email alerting: attempt 1
[2023-01-26 18:08:05,598] {taskinstance.py:1909} ERROR - Task failed with exception
Traceback (most recent call last):
  File "/home/airflow/.local/lib/python3.7/site-packages/airflow/operators/email.py", line 85, in execute
    custom_headers=self.custom_headers,
  File "/home/airflow/.local/lib/python3.7/site-packages/airflow/utils/email.py", line 71, in send_email
    **kwargs,
  File "/home/airflow/.local/lib/python3.7/site-packages/airflow/utils/email.py", line 119, in send_email_smtp
    send_mime_email(e_from=mail_from, e_to=recipients, mime_msg=msg, conn_id=conn_id, dryrun=dryrun)
  File "/home/airflow/.local/lib/python3.7/site-packages/airflow/utils/email.py", line 239, in send_mime_email
    smtp_conn.login(smtp_user, smtp_password)
  File "/usr/local/lib/python3.7/smtplib.py", line 735, in login
    raise last_exception
  File "/usr/local/lib/python3.7/smtplib.py", line 726, in login
    initial_response_ok=initial_response_ok)
  File "/usr/local/lib/python3.7/smtplib.py", line 647, in auth
    raise SMTPAuthenticationError(code, resp)
smtplib.SMTPAuthenticationError: (535, b'5.7.8 Username and Password not accepted. Learn more at\n5.7.8  https://support.google.com/mail/?p=BadCredentials h185-20020a376cc2000000b007069375e0f4sm1298100qkc.122 - gsmtp')
[2023-01-26 18:08:05,609] {taskinstance.py:1420} INFO - Marking task as UP_FOR_RETRY. dag_id=Respuesta_Nasa, task_id=send_email_notification, execution_date=20230101T000000, start_date=20230126T180804, end_date=20230126T180805
[2023-01-26 18:08:05,623] {warnings.py:110} WARNING - /home/***/.local/lib/python3.7/site-packages/***/utils/email.py:119: PendingDeprecationWarning: Fetching SMTP credentials from configuration variables will be deprecated in a future release. Please set credentials using a connection instead.
  send_mime_email(e_from=mail_from, e_to=recipients, mime_msg=msg, conn_id=conn_id, dryrun=dryrun)

[2023-01-26 18:08:05,623] {email.py:228} INFO - Email alerting: attempt 1
[2023-01-26 18:08:06,651] {email.py:228} INFO - Email alerting: attempt 1
[2023-01-26 18:08:07,651] {taskinstance.py:1964} ERROR - Failed to send email to: ['frandak2@gmail.com']
Traceback (most recent call last):
  File "/home/airflow/.local/lib/python3.7/site-packages/airflow/models/taskinstance.py", line 1471, in _run_raw_task
    self._execute_task_with_callbacks(context, test_mode)
  File "/home/airflow/.local/lib/python3.7/site-packages/airflow/models/taskinstance.py", line 1618, in _execute_task_with_callbacks
    result = self._execute_task(context, task_orig)
  File "/home/airflow/.local/lib/python3.7/site-packages/airflow/models/taskinstance.py", line 1679, in _execute_task
    result = execute_callable(context=context)
  File "/home/airflow/.local/lib/python3.7/site-packages/airflow/operators/email.py", line 85, in execute
    custom_headers=self.custom_headers,
  File "/home/airflow/.local/lib/python3.7/site-packages/airflow/utils/email.py", line 71, in send_email
    **kwargs,
  File "/home/airflow/.local/lib/python3.7/site-packages/airflow/utils/email.py", line 119, in send_email_smtp
    send_mime_email(e_from=mail_from, e_to=recipients, mime_msg=msg, conn_id=conn_id, dryrun=dryrun)
  File "/home/airflow/.local/lib/python3.7/site-packages/airflow/utils/email.py", line 239, in send_mime_email
    smtp_conn.login(smtp_user, smtp_password)
  File "/usr/local/lib/python3.7/smtplib.py", line 735, in login
    raise last_exception
  File "/usr/local/lib/python3.7/smtplib.py", line 726, in login
    initial_response_ok=initial_response_ok)
  File "/usr/local/lib/python3.7/smtplib.py", line 647, in auth
    raise SMTPAuthenticationError(code, resp)
smtplib.SMTPAuthenticationError: (535, b'5.7.8 Username and Password not accepted. Learn more at\n5.7.8  https://support.google.com/mail/?p=BadCredentials h185-20020a376cc2000000b007069375e0f4sm1298100qkc.122 - gsmtp')

During handling of the above exception, another exception occurred:

Traceback (most recent call last):
  File "/home/airflow/.local/lib/python3.7/site-packages/airflow/models/taskinstance.py", line 2346, in email_alert
    send_email(task.email, subject, html_content)
  File "/home/airflow/.local/lib/python3.7/site-packages/airflow/utils/email.py", line 71, in send_email
    **kwargs,
  File "/home/airflow/.local/lib/python3.7/site-packages/airflow/utils/email.py", line 119, in send_email_smtp
    send_mime_email(e_from=mail_from, e_to=recipients, mime_msg=msg, conn_id=conn_id, dryrun=dryrun)
  File "/home/airflow/.local/lib/python3.7/site-packages/airflow/utils/email.py", line 239, in send_mime_email
    smtp_conn.login(smtp_user, smtp_password)
  File "/usr/local/lib/python3.7/smtplib.py", line 735, in login
    raise last_exception
  File "/usr/local/lib/python3.7/smtplib.py", line 726, in login
    initial_response_ok=initial_response_ok)
  File "/usr/local/lib/python3.7/smtplib.py", line 647, in auth
    raise SMTPAuthenticationError(code, resp)
smtplib.SMTPAuthenticationError: (535, b'5.7.8 Username and Password not accepted. Learn more at\n5.7.8  https://support.google.com/mail/?p=BadCredentials b19-20020a05620a119300b00706b42c0842sm1304753qkk.49 - gsmtp')

During handling of the above exception, another exception occurred:

Traceback (most recent call last):
  File "/home/airflow/.local/lib/python3.7/site-packages/airflow/models/taskinstance.py", line 1962, in handle_failure
    self.email_alert(error, task)
  File "/home/airflow/.local/lib/python3.7/site-packages/airflow/models/taskinstance.py", line 2348, in email_alert
    send_email(task.email, subject, html_content_err)
  File "/home/airflow/.local/lib/python3.7/site-packages/airflow/utils/email.py", line 71, in send_email
    **kwargs,
  File "/home/airflow/.local/lib/python3.7/site-packages/airflow/utils/email.py", line 119, in send_email_smtp
    send_mime_email(e_from=mail_from, e_to=recipients, mime_msg=msg, conn_id=conn_id, dryrun=dryrun)
  File "/home/airflow/.local/lib/python3.7/site-packages/airflow/utils/email.py", line 239, in send_mime_email
    smtp_conn.login(smtp_user, smtp_password)
  File "/usr/local/lib/python3.7/smtplib.py", line 735, in login
    raise last_exception
  File "/usr/local/lib/python3.7/smtplib.py", line 726, in login
    initial_response_ok=initial_response_ok)
  File "/usr/local/lib/python3.7/smtplib.py", line 647, in auth
    raise SMTPAuthenticationError(code, resp)
smtplib.SMTPAuthenticationError: (535, b'5.7.8 Username and Password not accepted. Learn more at\n5.7.8  https://support.google.com/mail/?p=BadCredentials r17-20020ae9d611000000b006f9e103260dsm1312826qkk.91 - gsmtp')
[2023-01-26 18:08:07,666] {standard_task_runner.py:97} ERROR - Failed to execute job 655 for task send_email_notification ((535, b'5.7.8 Username and Password not accepted. Learn more at\n5.7.8  https://support.google.com/mail/?p=BadCredentials h185-20020a376cc2000000b007069375e0f4sm1298100qkc.122 - gsmtp'); 919)
[2023-01-26 18:08:07,693] {local_task_job.py:156} INFO - Task exited with return code 1
[2023-01-26 18:08:07,729] {local_task_job.py:273} INFO - 0 downstream tasks scheduled from follow-on schedule check
