[2023-01-27T15:18:16.315+0000] {taskinstance.py:1165} INFO - Dependencies all met for <TaskInstance: Respuesta_Nasa.send_email_notification scheduled__2023-01-01T00:00:00+00:00 [queued]>
[2023-01-27T15:18:16.330+0000] {taskinstance.py:1165} INFO - Dependencies all met for <TaskInstance: Respuesta_Nasa.send_email_notification scheduled__2023-01-01T00:00:00+00:00 [queued]>
[2023-01-27T15:18:16.330+0000] {taskinstance.py:1362} INFO - 
--------------------------------------------------------------------------------
[2023-01-27T15:18:16.331+0000] {taskinstance.py:1363} INFO - Starting attempt 22 of 24
[2023-01-27T15:18:16.331+0000] {taskinstance.py:1364} INFO - 
--------------------------------------------------------------------------------
[2023-01-27T15:18:16.347+0000] {taskinstance.py:1383} INFO - Executing <Task(EmailOperator): send_email_notification> on 2023-01-01 00:00:00+00:00
[2023-01-27T15:18:16.353+0000] {standard_task_runner.py:55} INFO - Started process 186 to run task
[2023-01-27T15:18:16.356+0000] {standard_task_runner.py:82} INFO - Running: ['***', 'tasks', 'run', 'Respuesta_Nasa', 'send_email_notification', 'scheduled__2023-01-01T00:00:00+00:00', '--job-id', '729', '--raw', '--subdir', 'DAGS_FOLDER/00-ETL_spaceX.py', '--cfg-path', '/tmp/tmpcj8yx86i']
[2023-01-27T15:18:16.358+0000] {standard_task_runner.py:83} INFO - Job 729: Subtask send_email_notification
[2023-01-27T15:18:16.452+0000] {task_command.py:376} INFO - Running <TaskInstance: Respuesta_Nasa.send_email_notification scheduled__2023-01-01T00:00:00+00:00 [running]> on host 3ceae0e2b238
[2023-01-27T15:18:16.567+0000] {taskinstance.py:1592} INFO - Exporting the following env vars:
AIRFLOW_CTX_DAG_EMAIL=frandak2@gmail.com
AIRFLOW_CTX_DAG_OWNER=***
AIRFLOW_CTX_DAG_ID=Respuesta_Nasa
AIRFLOW_CTX_TASK_ID=send_email_notification
AIRFLOW_CTX_EXECUTION_DATE=2023-01-01T00:00:00+00:00
AIRFLOW_CTX_TRY_NUMBER=22
AIRFLOW_CTX_DAG_RUN_ID=scheduled__2023-01-01T00:00:00+00:00
[2023-01-27T15:18:16.588+0000] {warnings.py:110} WARNING - /home/***/.local/lib/python3.7/site-packages/***/utils/email.py:120: RemovedInAirflow3Warning: Fetching SMTP credentials from configuration variables will be deprecated in a future release. Please set credentials using a connection instead.
  send_mime_email(e_from=mail_from, e_to=recipients, mime_msg=msg, conn_id=conn_id, dryrun=dryrun)

[2023-01-27T15:18:16.589+0000] {configuration.py:569} WARNING - section/key [smtp/smtp_user] not found in config
[2023-01-27T15:18:16.589+0000] {email.py:229} INFO - Email alerting: attempt 1
[2023-01-27T15:18:16.590+0000] {taskinstance.py:1851} ERROR - Task failed with exception
Traceback (most recent call last):
  File "/home/airflow/.local/lib/python3.7/site-packages/airflow/operators/email.py", line 87, in execute
    custom_headers=self.custom_headers,
  File "/home/airflow/.local/lib/python3.7/site-packages/airflow/utils/email.py", line 72, in send_email
    **kwargs,
  File "/home/airflow/.local/lib/python3.7/site-packages/airflow/utils/email.py", line 120, in send_email_smtp
    send_mime_email(e_from=mail_from, e_to=recipients, mime_msg=msg, conn_id=conn_id, dryrun=dryrun)
  File "/home/airflow/.local/lib/python3.7/site-packages/airflow/utils/email.py", line 231, in send_mime_email
    smtp_conn = _get_smtp_connection(smtp_host, smtp_port, smtp_timeout, smtp_ssl)
  File "/home/airflow/.local/lib/python3.7/site-packages/airflow/utils/email.py", line 265, in _get_smtp_connection
    else smtplib.SMTP(host=host, port=port, timeout=timeout)
  File "/usr/local/lib/python3.7/smtplib.py", line 251, in __init__
    (code, msg) = self.connect(host, port)
  File "/usr/local/lib/python3.7/smtplib.py", line 336, in connect
    self.sock = self._get_socket(host, port, self.timeout)
  File "/usr/local/lib/python3.7/smtplib.py", line 307, in _get_socket
    self.source_address)
  File "/usr/local/lib/python3.7/socket.py", line 728, in create_connection
    raise err
  File "/usr/local/lib/python3.7/socket.py", line 716, in create_connection
    sock.connect(sa)
OSError: [Errno 99] Cannot assign requested address
[2023-01-27T15:18:16.611+0000] {taskinstance.py:1406} INFO - Marking task as UP_FOR_RETRY. dag_id=Respuesta_Nasa, task_id=send_email_notification, execution_date=20230101T000000, start_date=20230127T151816, end_date=20230127T151816
[2023-01-27T15:18:16.633+0000] {warnings.py:110} WARNING - /home/***/.local/lib/python3.7/site-packages/***/utils/email.py:120: RemovedInAirflow3Warning: Fetching SMTP credentials from configuration variables will be deprecated in a future release. Please set credentials using a connection instead.
  send_mime_email(e_from=mail_from, e_to=recipients, mime_msg=msg, conn_id=conn_id, dryrun=dryrun)

[2023-01-27T15:18:16.634+0000] {configuration.py:569} WARNING - section/key [smtp/smtp_user] not found in config
[2023-01-27T15:18:16.634+0000] {email.py:229} INFO - Email alerting: attempt 1
[2023-01-27T15:18:16.646+0000] {configuration.py:569} WARNING - section/key [smtp/smtp_user] not found in config
[2023-01-27T15:18:16.647+0000] {email.py:229} INFO - Email alerting: attempt 1
[2023-01-27T15:18:16.648+0000] {taskinstance.py:1914} ERROR - Failed to send email to: ['frandak2@gmail.com']
Traceback (most recent call last):
  File "/home/airflow/.local/lib/python3.7/site-packages/airflow/models/taskinstance.py", line 1457, in _run_raw_task
    self._execute_task_with_callbacks(context, test_mode)
  File "/home/airflow/.local/lib/python3.7/site-packages/airflow/models/taskinstance.py", line 1603, in _execute_task_with_callbacks
    result = self._execute_task(context, task_orig)
  File "/home/airflow/.local/lib/python3.7/site-packages/airflow/models/taskinstance.py", line 1664, in _execute_task
    result = execute_callable(context=context)
  File "/home/airflow/.local/lib/python3.7/site-packages/airflow/operators/email.py", line 87, in execute
    custom_headers=self.custom_headers,
  File "/home/airflow/.local/lib/python3.7/site-packages/airflow/utils/email.py", line 72, in send_email
    **kwargs,
  File "/home/airflow/.local/lib/python3.7/site-packages/airflow/utils/email.py", line 120, in send_email_smtp
    send_mime_email(e_from=mail_from, e_to=recipients, mime_msg=msg, conn_id=conn_id, dryrun=dryrun)
  File "/home/airflow/.local/lib/python3.7/site-packages/airflow/utils/email.py", line 231, in send_mime_email
    smtp_conn = _get_smtp_connection(smtp_host, smtp_port, smtp_timeout, smtp_ssl)
  File "/home/airflow/.local/lib/python3.7/site-packages/airflow/utils/email.py", line 265, in _get_smtp_connection
    else smtplib.SMTP(host=host, port=port, timeout=timeout)
  File "/usr/local/lib/python3.7/smtplib.py", line 251, in __init__
    (code, msg) = self.connect(host, port)
  File "/usr/local/lib/python3.7/smtplib.py", line 336, in connect
    self.sock = self._get_socket(host, port, self.timeout)
  File "/usr/local/lib/python3.7/smtplib.py", line 307, in _get_socket
    self.source_address)
  File "/usr/local/lib/python3.7/socket.py", line 728, in create_connection
    raise err
  File "/usr/local/lib/python3.7/socket.py", line 716, in create_connection
    sock.connect(sa)
OSError: [Errno 99] Cannot assign requested address

During handling of the above exception, another exception occurred:

Traceback (most recent call last):
  File "/home/airflow/.local/lib/python3.7/site-packages/airflow/models/taskinstance.py", line 2315, in email_alert
    send_email(task.email, subject, html_content)
  File "/home/airflow/.local/lib/python3.7/site-packages/airflow/utils/email.py", line 72, in send_email
    **kwargs,
  File "/home/airflow/.local/lib/python3.7/site-packages/airflow/utils/email.py", line 120, in send_email_smtp
    send_mime_email(e_from=mail_from, e_to=recipients, mime_msg=msg, conn_id=conn_id, dryrun=dryrun)
  File "/home/airflow/.local/lib/python3.7/site-packages/airflow/utils/email.py", line 231, in send_mime_email
    smtp_conn = _get_smtp_connection(smtp_host, smtp_port, smtp_timeout, smtp_ssl)
  File "/home/airflow/.local/lib/python3.7/site-packages/airflow/utils/email.py", line 265, in _get_smtp_connection
    else smtplib.SMTP(host=host, port=port, timeout=timeout)
  File "/usr/local/lib/python3.7/smtplib.py", line 251, in __init__
    (code, msg) = self.connect(host, port)
  File "/usr/local/lib/python3.7/smtplib.py", line 336, in connect
    self.sock = self._get_socket(host, port, self.timeout)
  File "/usr/local/lib/python3.7/smtplib.py", line 307, in _get_socket
    self.source_address)
  File "/usr/local/lib/python3.7/socket.py", line 728, in create_connection
    raise err
  File "/usr/local/lib/python3.7/socket.py", line 716, in create_connection
    sock.connect(sa)
OSError: [Errno 99] Cannot assign requested address

During handling of the above exception, another exception occurred:

Traceback (most recent call last):
  File "/home/airflow/.local/lib/python3.7/site-packages/airflow/models/taskinstance.py", line 1912, in handle_failure
    self.email_alert(error, task)
  File "/home/airflow/.local/lib/python3.7/site-packages/airflow/models/taskinstance.py", line 2317, in email_alert
    send_email(task.email, subject, html_content_err)
  File "/home/airflow/.local/lib/python3.7/site-packages/airflow/utils/email.py", line 72, in send_email
    **kwargs,
  File "/home/airflow/.local/lib/python3.7/site-packages/airflow/utils/email.py", line 120, in send_email_smtp
    send_mime_email(e_from=mail_from, e_to=recipients, mime_msg=msg, conn_id=conn_id, dryrun=dryrun)
  File "/home/airflow/.local/lib/python3.7/site-packages/airflow/utils/email.py", line 231, in send_mime_email
    smtp_conn = _get_smtp_connection(smtp_host, smtp_port, smtp_timeout, smtp_ssl)
  File "/home/airflow/.local/lib/python3.7/site-packages/airflow/utils/email.py", line 265, in _get_smtp_connection
    else smtplib.SMTP(host=host, port=port, timeout=timeout)
  File "/usr/local/lib/python3.7/smtplib.py", line 251, in __init__
    (code, msg) = self.connect(host, port)
  File "/usr/local/lib/python3.7/smtplib.py", line 336, in connect
    self.sock = self._get_socket(host, port, self.timeout)
  File "/usr/local/lib/python3.7/smtplib.py", line 307, in _get_socket
    self.source_address)
  File "/usr/local/lib/python3.7/socket.py", line 728, in create_connection
    raise err
  File "/usr/local/lib/python3.7/socket.py", line 716, in create_connection
    sock.connect(sa)
OSError: [Errno 99] Cannot assign requested address
[2023-01-27T15:18:16.668+0000] {standard_task_runner.py:105} ERROR - Failed to execute job 729 for task send_email_notification ([Errno 99] Cannot assign requested address; 186)
[2023-01-27T15:18:16.688+0000] {local_task_job.py:159} INFO - Task exited with return code 1
[2023-01-27T15:18:16.773+0000] {taskinstance.py:2623} INFO - 0 downstream tasks scheduled from follow-on schedule check
